Workbook

Sheet Informe BBVA
A1: F.Valor | B1: Fecha | C1: Periodo | D1: Concepto | E1: Movimiento | F1: Importe | G1: Divisa | H1: Disponible | I1: Divisa2 | J1: Observaciones | K1: Subcatergoria | L1: Categoria
A2: 31/10/2025 | B2: 31/10/2025 | C2: =MONTH(A2) -> 10 | D2: Acciona motosharing | E2: Pago con tarjeta | F2: -4.88 | G2: EUR | H2: 5664.75 | I2: EUR | J2: 4940197133530195 ACCIONA MOTOSHARING ALCOBENDAS ES | K2: Transporte | L2: =VLOOKUP(K2,'COD.'!$A$1:$B$39,2,0) -> Otros Gastos Generales
A3: 30/10/2025 | B3: 31/10/2025 | C3: =MONTH(A3) -> 10 | D3: Netflix.com | E3: Pago con tarjeta | F3: -6.99 | G3: EUR | H3: 5669.63 | I3: EUR | J3: 4940197133530195 Netflix.com | K3: Netfix | L3: =VLOOKUP(K3,'COD.'!$A$1:$B$39,2,0) -> Ocio y Entretenimiento
A4: 31/10/2025 | B4: 31/10/2025 | C4: =MONTH(A4) -> 10 | D4: Adeudo de endesa | E4: Adeudo nº 2025303002749399 | F4: -67.81 | G4: EUR | H4: 5676.62 | I4: EUR | J4: N 2025303002749399 ENERGIA XXI CPVR | K4: Luz | L4: =VLOOKUP(K4,'COD.'!$A$1:$B$39,2,0) -> Suministros
A5: 31/10/2025 | B5: 31/10/2025 | C5: =MONTH(A5) -> 10 | D5: Cargo por amortizacion de prestamo/credito | F5: -461.91 | G5: EUR | H5: 5744.43 | I5: EUR | J5: 0182-3247-22-0830147409 | K5: Hipoteca | L5: =VLOOKUP(K5,'COD.'!$A$1:$B$39,2,0) -> Vivienda y Préstamos
A6: 30/10/2025 | B6: 30/10/2025 | C6: =MONTH(A6) -> 10 | D6: Frankingfurt | E6: Pago con tarjeta | F6: -21.6 | G6: EUR | H6: 6206.34 | I6: EUR | J6: 4940197133530195 FRANKINGFURT SANTA COLOMA ES | K6: Bar/Restaurante | L6: =VLOOKUP(K6,'COD.'!$A$1:$B$39,2,0) -> Ocio y Entretenimiento
A7: 30/10/2025 | B7: 30/10/2025 | C7: =MONTH(A7) -> 10 | D7: Bar cafeteria | E7: Pago con tarjeta | F7: -3.9 | G7: EUR | H7: 6227.94 | I7: EUR | J7: 4940197133530195 BAR CAFETERIA SANTA COLOMA ES | K7: Bar/Restaurante | L7: =VLOOKUP(K7,'COD.'!$A$1:$B$39,2,0) -> Ocio y Entretenimiento
A8: 30/10/2025 | B8: 30/10/2025 | C8: =MONTH(A8) -> 10 | D8: Adeudo de aguas de barcelona | E8: Adeudo nº 2025303002474367 | F8: -44.47 | G8: EUR | H8: 6231.84 | I8: EUR | J8: N 2025303002474367 AIGUES DE BARCELONA | K8: Agua | L8: =VLOOKUP(K8,'COD.'!$A$1:$B$39,2,0) -> Suministros
A9: 30/10/2025 | B9: 30/10/2025 | C9: =MONTH(A9) -> 10 | D9: Abono de nómina | E9: Transferencia nomina | F9: 1867.53 | G9: EUR | H9: 6276.31 | I9: EUR | J9: Transferencia nomina | K9: Nomina | L9: =VLOOKUP(K9,'COD.'!$A$1:$B$39,2,0) -> Transferencias y Efectivo
A10: 28/10/2025 | B10: 28/10/2025 | C10: =MONTH(A10) -> 10 | D10: Social working dogs sccl | E10: Pago con tarjeta | F10: -29.95 | G10: EUR | H10: 4408.78 | I10: EUR | J10: 4940197133530195 SOCIAL WORKING DOGS SCCL LLIA D'AMUNTES | K10: Mascotas | L10: =VLOOKUP(K10,'COD.'!$A$1:$B$39,2,0) -> Supermercado
A11: 23/10/2025 | B11: 27/10/2025 | C11: =MONTH(A11) -> 10 | D11: Paypal *spotify*p3bbd12eb | E11: Pago con tarjeta | F11: -11.99 | G11: EUR | H11: 4438.73 | I11: EUR | J11: 4940197133530195 PAYPAL *SPOTIFY*P3BBD12EB | K11: Spotify | L11: =VLOOKUP(K11,'COD.'!$A$1:$B$39,2,0) -> Ocio y Entretenimiento
A12: 26/10/2025 | B12: 27/10/2025 | C12: =MONTH(A12) -> 10 | D12: Farmacia jordi bomcompte | E12: Pago con tarjeta | F12: -3.26 | G12: EUR | H12: 4450.72 | I12: EUR | J12: 4940197133530195 FARMACIA JORDI BOMCOMPTE PLA, PASSATGEES | K12: Farmacia | L12: =VLOOKUP(K12,'COD.'!$A$1:$B$39,2,0) -> Salud y Cuidado
A13: 25/10/2025 | B13: 27/10/2025 | C13: =MONTH(A13) -> 10 | D13: Kiwoko fabra | E13: Pago con tarjeta | F13: -17.89 | G13: EUR | H13: 4453.98 | I13: EUR | J13: 4940197133530195 KIWOKO FABRA BARCELONA ES | K13: Mascotas | L13: =VLOOKUP(K13,'COD.'!$A$1:$B$39,2,0) -> Supermercado
A14: 25/10/2025 | B14: 27/10/2025 | C14: =MONTH(A14) -> 10 | D14: Bar-rest. bell more | E14: Pago con tarjeta | F14: -2.9 | G14: EUR | H14: 4471.87 | I14: EUR | J14: 4940197133530195 Bar-Rest. Bell More BARCELONA ES | K14: Bar/Restaurante | L14: =VLOOKUP(K14,'COD.'!$A$1:$B$39,2,0) -> Ocio y Entretenimiento
A15: 24/10/2025 | B15: 27/10/2025 | C15: =MONTH(A15) -> 10 | D15: Bar lido | E15: Pago con tarjeta | F15: -7.95 | G15: EUR | H15: 4474.77 | I15: EUR | J15: 4940197133530195 BAR LIDO BARCELONA ES | K15: Bar/Restaurante | L15: =VLOOKUP(K15,'COD.'!$A$1:$B$39,2,0) -> Ocio y Entretenimiento
A16: 24/10/2025 | B16: 24/10/2025 | C16: =MONTH(A16) -> 10 | D16: Hyde park | E16: Pago con tarjeta | F16: -1.7 | G16: EUR | H16: 4482.72 | I16: EUR | J16: 4940197133530195 HYDE PARK BARCELONA ES | K16: Bar/Restaurante | L16: =VLOOKUP(K16,'COD.'!$A$1:$B$39,2,0) -> Ocio y Entretenimiento
A17: 24/10/2025 | B17: 24/10/2025 | C17: =MONTH(A17) -> 10 | D17: L estanc de la merce | E17: Pago con tarjeta | F17: -6.3 | G17: EUR | H17: 4484.42 | I17: EUR | J17: 4940197133530195 L ESTANC DE LA MERCE BARCELONA ES | K17: Tabaco | L17: =VLOOKUP(K17,'COD.'!$A$1:$B$39,2,0) -> Otros Gastos Generales
... A86: 30/09/2025 | B86: 30/09/2025 | C86: =MONTH(A86) -> 9 | D86: Druni sta coloma gramenet | E86: Pago con tarjeta | F86: -26.95 | G86: EUR | H86: 6060.2 | I86: EUR | J86: 4940197133530195 DRUNI STA COLOMA GRAMENETSANTA COLOMA ES | K86: Compras | L86: =VLOOKUP(K86,'COD.'!$A$1:$B$39,2,0) -> Ocio y Entretenimiento
A87: 30/09/2025 | B87: 30/09/2025 | C87: =MONTH(A87) -> 9 | D87: Cargo por amortizacion de prestamo/credito | F87: -461.91 | G87: EUR | H87: 6087.15 | I87: EUR | J87: 0182-3247-22-0830147409 | K87: Hipoteca | L87: =VLOOKUP(K87,'COD.'!$A$1:$B$39,2,0) -> Vivienda y Préstamos
A88: 29/09/2025 | B88: 29/09/2025 | C88: =MONTH(A88) -> 9 | D88: Kiwoko fabra | E88: Pago con tarjeta | F88: -38.65 | G88: EUR | H88: 6549.06 | I88: EUR | J88: 4940197133530195 KIWOKO FABRA BARCELONA ES | K88: Mascotas | L88: =VLOOKUP(K88,'COD.'!$A$1:$B$39,2,0) -> Supermercado
A89: 28/09/2025 | B89: 29/09/2025 | C89: =MONTH(A89) -> 9 | D89: Condis supermercat | E89: Pago con tarjeta | F89: -5.23 | G89: EUR | H89: 6587.71 | I89: EUR | J89: 4940197133530195 CONDIS SUPERMERCAT STA. COLOMA DES | K89: Supermercado | L89: =VLOOKUP(K89,'COD.'!$A$1:$B$39,2,0) -> Supermercado
A90: 26/09/2025 | B90: 26/09/2025 | C90: =MONTH(A90) -> 9 | D90: La santa | E90: Pago con tarjeta | F90: -4.1 | G90: EUR | H90: 6592.94 | I90: EUR | J90: 4940197133530195 LA SANTA ESPLUGUES DE ES | K90: Bar/Restaurante | L90: =VLOOKUP(K90,'COD.'!$A$1:$B$39,2,0) -> Ocio y Entretenimiento
A91: 26/09/2025 | B91: 26/09/2025 | C91: =MONTH(A91) -> 9 | D91: Terranova 55 | E91: Pago con tarjeta | F91: -36.95 | G91: EUR | H91: 6597.04 | I91: EUR | J91: 4940197133530195 TERRANOVA 55 SANTA COLOMA ES | K91: Mascotas | L91: =VLOOKUP(K91,'COD.'!$A$1:$B$39,2,0) -> Supermercado
A92: 26/09/2025 | B92: 26/09/2025 | C92: =MONTH(A92) -> 9 | D92: Forn padro | E92: Pago con tarjeta | F92: -1.55 | G92: EUR | H92: 6633.99 | I92: EUR | J92: 4940197133530195 FORN PADRO SANTA COLOMA ES | K92: Bar/Restaurante | L92: =VLOOKUP(K92,'COD.'!$A$1:$B$39,2,0) -> Ocio y Entretenimiento
A93: 26/09/2025 | B93: 26/09/2025 | C93: =MONTH(A93) -> 9 | D93: Abono de nómina | E93: Transferencia nomina | F93: 1867.53 | G93: EUR | H93: 6635.54 | I93: EUR | J93: Transferencia nomina | K93: Nomina | L93: =VLOOKUP(K93,'COD.'!$A$1:$B$39,2,0) -> Transferencias y Efectivo
A94: 26/09/2025 | B94: 26/09/2025 | C94: =MONTH(A94) -> 9 | D94: Condis supermercat | E94: Pago con tarjeta | F94: -1.02 | G94: EUR | H94: 4768.01 | I94: EUR | J94: 4940197133530195 CONDIS SUPERMERCAT STA. COLOMA DES | K94: Supermercado | L94: =VLOOKUP(K94,'COD.'!$A$1:$B$39,2,0) -> Supermercado
A95: 26/09/2025 | B95: 26/09/2025 | C95: =MONTH(A95) -> 9 | D95: Rostisseria la katia | E95: Pago con tarjeta | F95: -22.75 | G95: EUR | H95: 4769.03 | I95: EUR | J95: 4940197133530195 ROSTISSERIA LA KATIA STA. COLOMA DES | K95: Bar/Restaurante | L95: =VLOOKUP(K95,'COD.'!$A$1:$B$39,2,0) -> Ocio y Entretenimiento
A96: 26/09/2025 | B96: 26/09/2025 | C96: =MONTH(A96) -> 9 | D96: Farmacia jordi bomcompte | E96: Pago con tarjeta | F96: -3.26 | G96: EUR | H96: 4791.78 | I96: EUR | J96: 4940197133530195 FARMACIA JORDI BOMCOMPTE SANTA COLOMA ES | K96: Farmacia | L96: =VLOOKUP(K96,'COD.'!$A$1:$B$39,2,0) -> Salud y Cuidado
A97: 25/09/2025 | B97: 26/09/2025 | C97: =MONTH(A97) -> 9 | D97: Frankingfurt | E97: Pago con tarjeta | F97: -15.7 | G97: EUR | H97: 4795.04 | I97: EUR | J97: 4940197133530195 FRANKINGFURT SANTA COLOMA ES | K97: Bar/Restaurante | L97: =VLOOKUP(K97,'COD.'!$A$1:$B$39,2,0) -> Ocio y Entretenimiento
A98: 25/09/2025 | B98: 25/09/2025 | C98: =MONTH(A98) -> 9 | D98: La botiga mes que gossos | E98: Pago con tarjeta | F98: -27.8 | G98: EUR | H98: 4810.74 | I98: EUR | J98: 4940197133530195 LA BOTIGA MES QUE GOSSOS SANTA COLOMA ES | K98: Mascotas | L98: =VLOOKUP(K98,'COD.'!$A$1:$B$39,2,0) -> Supermercado
A99: 25/09/2025 | B99: 25/09/2025 | C99: =MONTH(A99) -> 9 | D99: Cerveceria thor | E99: Pago con tarjeta | F99: -1.7 | G99: EUR | H99: 4838.54 | I99: EUR | J99: 4940197133530195 cerveceria thor PLA, PASSATGEES | K99: Bar/Restaurante | L99: =VLOOKUP(K99,'COD.'!$A$1:$B$39,2,0) -> Ocio y Entretenimiento
... A177: 31/08/2025 | B177: 01/09/2025 | C177: =MONTH(A177) -> 8 | D177: Cerveceria thor | E177: Pago con tarjeta | F177: -1.2 | G177: EUR | H177: 6401.64 | I177: EUR | J177: 4940197133530195 cerveceria thor PLA, PASSATGEES | K177: Bar/Restaurante | L177: =VLOOKUP(K177,'COD.'!$A$1:$B$39,2,0) -> Ocio y Entretenimiento
A178: 31/08/2025 | B178: 01/09/2025 | C178: =MONTH(A178) -> 8 | D178: Cargo por amortizacion de prestamo/credito | F178: -461.91 | G178: EUR | H178: 6402.84 | I178: EUR | J178: 0182-3247-22-0830147409 | K178: Hipoteca | L178: =VLOOKUP(K178,'COD.'!$A$1:$B$39,2,0) -> Vivienda y Préstamos
A179: 30/08/2025 | B179: 01/09/2025 | C179: =MONTH(A179) -> 8 | D179: La rotonda masnou | E179: Pago con tarjeta | F179: -9 | G179: EUR | H179: 6864.75 | I179: EUR | J179: 4940197133530195 LA ROTONDA MASNOU EL MASNOU ES | K179: Bar/Restaurante | L179: =VLOOKUP(K179,'COD.'!$A$1:$B$39,2,0) -> Ocio y Entretenimiento
A180: 30/08/2025 | B180: 01/09/2025 | C180: =MONTH(A180) -> 8 | D180: Macxipa avda. generalitat | E180: Pago con tarjeta | F180: -2.26 | G180: EUR | H180: 6873.75 | I180: EUR | J180: 4940197133530195 MACXIPA AVDA. GENERALITATSTA. COLOMA ES | K180: Bar/Restaurante | L180: =VLOOKUP(K180,'COD.'!$A$1:$B$39,2,0) -> Ocio y Entretenimiento
A181: 29/08/2025 | B181: 29/08/2025 | C181: =MONTH(A181) -> 8 | D181: Druni sta coloma gramenet | E181: Pago con tarjeta | F181: -1.99 | G181: EUR | H181: 6876.01 | I181: EUR | J181: 4940197133530195 DRUNI STA COLOMA GRAMENETSANTA COLOMA ES | K181: compras | L181: =VLOOKUP(K181,'COD.'!$A$1:$B$39,2,0) -> Ocio y Entretenimiento
A182: 29/08/2025 | B182: 29/08/2025 | C182: =MONTH(A182) -> 8 | D182: Abono por fraccionamiento de gastos | E182: Abono capital préstamo | F182: 699.84 | G182: EUR | H182: 6878 | I182: EUR | J182: 8123450000175812 01827013 704 | K182: Cuota mensual de fraccionamiento de gastos | L182: =VLOOKUP(K182,'COD.'!$A$1:$B$39,2,0) -> Vivienda y Préstamos
A183: 28/08/2025 | B183: 29/08/2025 | C183: =MONTH(A183) -> 8 | D183: 0453-consum b. fabra y pu | E183: Pago con tarjeta | F183: -11.5 | G183: EUR | H183: 6178.16 | I183: EUR | J183: 4940197133530195 0453-CONSUM B. FABRA Y PUBARCELONA ES | K183: Supermercado | L183: =VLOOKUP(K183,'COD.'!$A$1:$B$39,2,0) -> Supermercado
A184: 28/08/2025 | B184: 29/08/2025 | C184: =MONTH(A184) -> 8 | D184: Cal pesca | E184: Pago con tarjeta | F184: -26.2 | G184: EUR | H184: 6189.66 | I184: EUR | J184: 4940197133530195 CAL PESCA BARCELONA ES | K184: Bar/Restaurante | L184: =VLOOKUP(K184,'COD.'!$A$1:$B$39,2,0) -> Ocio y Entretenimiento
A185: 28/08/2025 | B185: 28/08/2025 | C185: =MONTH(A185) -> 8 | D185: Estanco expendiduria 134 | E185: Pago con tarjeta | F185: -1.5 | G185: EUR | H185: 6215.86 | I185: EUR | J185: 4940197133530195 ESTANCO EXPENDIDURIA 134 BARCELONA ES | K185: Tabaco | L185: =VLOOKUP(K185,'COD.'!$A$1:$B$39,2,0) -> Otros Gastos Generales
...

Sheet TD
A3: Suma de Importe | C3: Periodo
A4: Categoria | B4: Subcatergoria | C4: 1 | D4: 2 | E4: 3 | F4: 4 | G4: 5 | H4: 6 | I4: 7 | J4: 8 | K4: 9 | L4: 10 | M4: Total general
A5: BBVA | B5: Comision | C5: -35 | M5: -35
A6: Total BBVA | C6: -35 | M6: -35
A7: Moto | B7: Gasolina | C7: -11.32 | D7: -12.35 | F7: -12 | G7: -11 | H7: -11.86 | I7: -21.9 | K7: -79.37 | L7: -11 | M7: -170.8
B8: ITV | E8: -21.29 | M8: -21.29
B9: Parking | C9: -30 | D9: -30 | E9: -30 | F9: -30 | G9: -30 | H9: -30 | I9: -30 | J9: -30 | K9: -30 | L9: -30 | M9: -300
A10: Total Moto | C10: -41.32 | D10: -42.35 | E10: -51.29 | F10: -42 | G10: -41 | H10: -41.86 | I10: -51.9 | J10: -30 | K10: -109.37 | L10: -41 | M10: -492.09
A11: Ocio y Entretenimiento | B11: Apple cloud | C11: -2.99 | D11: -2.99 | E11: -2.99 | F11: -2.99 | G11: -2.99 | H11: -2.99 | I11: -2.99 | J11: -2.99 | K11: -5.48 | L11: -5.48 | M11: -34.88
B12: Bar/Restaurante | C12: -320.8 | D12: -18 | E12: -150.44 | F12: -286.98 | G12: -191.4 | H12: -228.15 | I12: -162.78 | J12: -439.01 | K12: -313.93 | L12: -174.61 | M12: -2286.1
B13: Compras | C13: -109.65 | D13: -130.86 | E13: -144.97 | F13: -157.68 | G13: -284 | H13: -172.32 | I13: -359.15 | J13: -468.61 | K13: -166.83 | L13: -167.65 | M13: -2161.72
B14: Gimnasio | D14: -65 | E14: -65 | F14: -65 | G14: -65 | H14: -65 | I14: -65 | J14: -32.5 | K14: -65 | L14: -65 | M14: -552.5
B15: Limpieza casa | E15: 72 | F15: -120 | G15: 42 | H15: -8 | I15: 72 | J15: 72 | K15: -90 | L15: 35.75 | M15: 75.75
B16: Loteria | C16: -10 | D16: -20 | E16: -10 | F16: -10 | G16: -10 | H16: -20 | L16: -10 | M16: -90
B17: Netfix | C17: -9.99 | D17: -9.99 | E17: -9.99 | F17: -9.99 | G17: -9.99 | H17: -6.99 | I17: -6.99 | J17: -6.99 | K17: -6.99 | L17: -6.99 | M17: -84.9
B18: Ocio | C18: -69 | F18: -56 | G18: -40 | H18: -103.3 | J18: -61.4 | L18: -3 | M18: -332.7
B19: Peluqueria | D19: -75 | F19: -90 | G19: -80 | M19: -245
B20: Podimo | H20: -0.99 | I20: -0.99 | J20: -0.99 | K20: -4.99 | L20: -4.99 | M20: -12.95
B21: Prime | I21: -49.9 | M21: -49.9
B22: Spotify | D22: -10.99 | E22: -10.99 | F22: -10.99 | G22: -10.99 | H22: -10.99 | I22: -10.99 | J22: -10.99 | K22: -11.99 | L22: -11.99 | M22: -100.91
B23: Uñas | F23: -42 | G23: -52 | H23: -49 | I23: -44 | M23: -187
B24: Viajes | F24: -641.4 | G24: -304 | I24: -208.63 | J24: -966.43 | K24: -165 | M24: -2285.46
A25: Total Ocio y Entretenimiento | C25: -522.43 | D25: -332.83 | E25: -322.38 | F25: -1493.03 | G25: -1008.37 | H25: -667.73 | I25: -839.42 | J25: -1917.91 | K25: -830.21 | L25: -413.96 | M25: -8348.27
A26: Otros Gastos Generales | B26: Donacion | C26: -9 | D26: -9 | E26: -9 | F26: -9 | G26: -9 | H26: -9 | I26: -9 | J26: -9 | K26: -9 | L26: -9 | M26: -90
B27: Tabaco | C27: -14.8 | D27: -15.4 | E27: -8.4 | F27: -18.2 | G27: -10.8 | H27: -23 | I27: -20.05 | J27: -16.5 | K27: -15.4 | L27: -34.7 | M27: -177.25
B28: Transporte | C28: -26.3 | E28: -26.26 | F28: -22.69 | G28: -8.66 | H28: -12.55 | J28: -17.97 | L28: -4.88 | M28: -119.31
A29: Total Otros Gastos Generales | C29: -50.1 | D29: -24.4 | E29: -43.66 | F29: -49.89 | G29: -28.46 | H29: -44.55 | I29: -29.05 | J29: -43.47 | K29: -24.4 | L29: -48.58 | M29: -386.56
A30: Salud y Cuidado | B30: Farmacia | C30: -121.03 | E30: -43.91 | F30: -57.9 | G30: -77.26 | H30: -329.11 | I30: -36.34 | J30: -81.86 | K30: -34.8 | L30: -222.79 | M30: -1005
A31: Total Salud y Cuidado | C31: -121.03 | E31: -43.91 | F31: -57.9 | G31: -77.26 | H31: -329.11 | I31: -36.34 | J31: -81.86 | K31: -34.8 | L31: -222.79 | M31: -1005
A32: Suministros | B32: Agua | D32: -44.2 | F32: -43.58 | H32: -44.47 | J32: -44.47 | L32: -44.47 | M32: -221.19
B33: Luz | C33: -125.9 | D33: -126.11 | E33: -214.2 | F33: -73.96 | H33: -103.37 | I33: -89.77 | K33: -88.34 | L33: -120.83 | M33: -942.48
B34: Vodafone | C34: -38.2 | D34: -38.2 | E34: -38.2 | F34: -38.2 | G34: -38.2 | H34: -38.2 | I34: -38.2 | J34: -38.2 | K34: -48.19 | L34: -42.2 | M34: -395.99
A35: Total Suministros | C35: -164.1 | D35: -208.51 | E35: -252.4 | F35: -155.74 | G35: -38.2 | H35: -186.04 | I35: -127.97 | J35: -82.67 | K35: -136.53 | L35: -207.5 | M35: -1559.66
A36: Supermercado | B36: Mascotas | C36: -52 | D36: -235.4 | E36: -80.67 | F36: -91.71 | G36: -155.14 | H36: -116.32 | I36: -122.05 | J36: -25.66 | K36: -157.1 | L36: -192 | M36: -1228.05
B37: Supermercado | C37: -197.18 | D37: -184.63 | E37: -120.26 | F37: -153.75 | G37: -143.9 | H37: -226.92 | I37: -157.6 | J37: -148.16 | K37: -188.37 | L37: -269.35 | M37: -1790.12
A38: Total Supermercado | C38: -249.18 | D38: -420.03 | E38: -200.93 | F38: -245.46 | G38: -299.04 | H38: -343.24 | I38: -279.65 | J38: -173.82 | K38: -345.47 | L38: -461.35 | M38: -3018.17
A39: Transferencias y Efectivo | B39: Bit2me | C39: 0 | M39: 0
B40: Bizum | C40: 122 | D40: 2 | E40: -381.67 | F40: 183.94 | G40: -58.75 | H40: -136 | I40: -75 | J40: 321 | K40: 100.09 | L40: -21 | M40: 56.61
B41: Efectivo | J41: 300 | M41: 300
B42: Nomina | C42: 1867.53 | D42: 1867.53 | E42: 1867.53 | F42: 1867.53 | G42: 1817.53 | H42: 1867.53 | I42: 1867.53 | J42: 1867.53 | K42: 1867.53 | L42: 1867.53 | M42: 18625.3
...

Sheet COD.
A1: Subcatergoria | B1: Categoria
A2: Agua | B2: Suministros
A3: Apple cloud | B3: Ocio y Entretenimiento
A4: Bar/Restaurante | B4: Ocio y Entretenimiento
A5: BBVA Seguro | B5: Vivienda y Préstamos
A6: Bit2me | B6: Transferencias y Efectivo
A7: Bizum | B7: Transferencias y Efectivo
A8: Casa | B8: Vivienda y Préstamos
A9: Comision | B9: BBVA
A10: Compras | B10: Ocio y Entretenimiento
A11: Cuota mensual de fraccionamiento de gastos | B11: Vivienda y Préstamos
A12: Donacion | B12: Otros Gastos Generales
... A39: Vodafone | B39: Suministros
